<?xml version="1.0" ?>
<robot name="dexhand-left" xmlns:xacro="http://www.ros.org/wiki/xacro">

<xacro:include filename="$(find dexhand_description)/urdf/materials.xacro" />
<xacro:include filename="$(find dexhand_description)/urdf/dexhand-left.trans" />
<xacro:include filename="$(find dexhand_description)/urdf/dexhand-left.gazebo" />
<link name="base_link">
  <inertial>
    <origin xyz="-5.952490372344805e-18 -5.952490372344805e-18 0.00625299730853927" rpy="0 0 0"/>
    <mass value="0.3748186138447861"/>
    <inertia ixx="0.000121" iyy="0.000121" izz="0.000233" ixy="0.0" iyz="-0.0" ixz="-0.0"/>
  </inertial>
  <visual>
    <origin xyz="0 0 0" rpy="0 0 0"/>
    <geometry>
      <mesh filename="package://dexhand_description/meshes/left/base_link.stl" scale="0.001 0.001 0.001"/>
    </geometry>
    <material name="silver"/>
  </visual>
  <collision>
    <origin xyz="0 0 0" rpy="0 0 0"/>
    <geometry>
      <mesh filename="package://dexhand_description/meshes/left/base_link.stl" scale="0.001 0.001 0.001"/>
    </geometry>
  </collision>
</link>

<link name="forearm_left_1">
  <inertial>
    <origin xyz="-0.004563551740542068 0.0024890031613358375 0.09119373569002041" rpy="0 0 0"/>
    <mass value="2.2753129035055744"/>
    <inertia ixx="0.009336" iyy="0.00912" izz="0.00247" ixy="3.2e-05" iyz="-4e-06" ixz="0.000837"/>
  </inertial>
  <visual>
    <origin xyz="-0.0 -0.0 -0.0" rpy="0 0 0"/>
    <geometry>
      <mesh filename="package://dexhand_description/meshes/left/forearm_left_1.stl" scale="0.001 0.001 0.001"/>
    </geometry>
    <material name="silver"/>
  </visual>
  <collision>
    <origin xyz="-0.0 -0.0 -0.0" rpy="0 0 0"/>
    <geometry>
      <mesh filename="package://dexhand_description/meshes/left/forearm_left_1.stl" scale="0.001 0.001 0.001"/>
    </geometry>
  </collision>
</link>

<link name="wrist_lower_1">
  <inertial>
    <origin xyz="-3.068376379026551e-05 0.02099365535807375 0.021635071099651598" rpy="0 0 0"/>
    <mass value="0.3236409508310491"/>
    <inertia ixx="0.000132" iyy="0.000118" izz="0.000139" ixy="-0.0" iyz="-0.0" ixz="-0.0"/>
  </inertial>
  <visual>
    <origin xyz="0.012 0.0203 -0.203" rpy="0 0 0"/>
    <geometry>
      <mesh filename="package://dexhand_description/meshes/left/wrist_lower_1.stl" scale="0.001 0.001 0.001"/>
    </geometry>
    <material name="silver"/>
  </visual>
  <collision>
    <origin xyz="0.012 0.0203 -0.203" rpy="0 0 0"/>
    <geometry>
      <mesh filename="package://dexhand_description/meshes/left/wrist_lower_1.stl" scale="0.001 0.001 0.001"/>
    </geometry>
  </collision>
</link>

<link name="wrist_upper_1">
  <inertial>
    <origin xyz="0.011943478530919057 1.9763952347645088e-08 0.007146961841600907" rpy="0 0 0"/>
    <mass value="0.12131953205677495"/>
    <inertia ixx="3.3e-05" iyy="2.2e-05" izz="2.6e-05" ixy="0.0" iyz="-0.0" ixz="-0.0"/>
  </inertial>
  <visual>
    <origin xyz="0.02388 -0.0007 -0.232" rpy="0 0 0"/>
    <geometry>
      <mesh filename="package://dexhand_description/meshes/left/wrist_upper_1.stl" scale="0.001 0.001 0.001"/>
    </geometry>
    <material name="silver"/>
  </visual>
  <collision>
    <origin xyz="0.02388 -0.0007 -0.232" rpy="0 0 0"/>
    <geometry>
      <mesh filename="package://dexhand_description/meshes/left/wrist_upper_1.stl" scale="0.001 0.001 0.001"/>
    </geometry>
  </collision>
</link>

<link name="index_bulk_left_1">
  <inertial>
    <origin xyz="0.0019538273380790318 -0.005732494629266137 0.04310724149718498" rpy="0 0 0"/>
    <mass value="0.10571523671577603"/>
    <inertia ixx="0.000112" iyy="0.000114" izz="8e-06" ixy="0.0" iyz="6e-06" ixz="-7e-06"/>
  </inertial>
  <visual>
    <origin xyz="0.01188 0.0203 -0.255266" rpy="0 0 0"/>
    <geometry>
      <mesh filename="package://dexhand_description/meshes/left/index_bulk_left_1.stl" scale="0.001 0.001 0.001"/>
    </geometry>
    <material name="silver"/>
  </visual>
  <collision>
    <origin xyz="0.01188 0.0203 -0.255266" rpy="0 0 0"/>
    <geometry>
      <mesh filename="package://dexhand_description/meshes/left/index_bulk_left_1.stl" scale="0.001 0.001 0.001"/>
    </geometry>
  </collision>
</link>

<link name="middle_bulk_left_1">
  <inertial>
    <origin xyz="0.010646693885552101 0.015813587520650638 0.0306892321585171" rpy="0 0 0"/>
    <mass value="0.23199619688762876"/>
    <inertia ixx="0.000258" iyy="0.000268" izz="7.1e-05" ixy="1.4e-05" iyz="-4.2e-05" ixz="4e-05"/>
  </inertial>
  <visual>
    <origin xyz="0.011884 0.0263 -0.254814" rpy="0 0 0"/>
    <geometry>
      <mesh filename="package://dexhand_description/meshes/left/middle_bulk_left_1.stl" scale="0.001 0.001 0.001"/>
    </geometry>
    <material name="silver"/>
  </visual>
  <collision>
    <origin xyz="0.011884 0.0263 -0.254814" rpy="0 0 0"/>
    <geometry>
      <mesh filename="package://dexhand_description/meshes/left/middle_bulk_left_1.stl" scale="0.001 0.001 0.001"/>
    </geometry>
  </collision>
</link>

<link name="ring_bulk_left_1">
  <inertial>
    <origin xyz="0.003391564401113451 0.010251244048412596 0.05277766582318083" rpy="0 0 0"/>
    <mass value="0.09588693536899053"/>
    <inertia ixx="7.4e-05" iyy="7.4e-05" izz="7e-06" ixy="-1e-06" iyz="-8e-06" ixz="-7e-06"/>
  </inertial>
  <visual>
    <origin xyz="0.011884 -0.0027 -0.254814" rpy="0 0 0"/>
    <geometry>
      <mesh filename="package://dexhand_description/meshes/left/ring_bulk_left_1.stl" scale="0.001 0.001 0.001"/>
    </geometry>
    <material name="silver"/>
  </visual>
  <collision>
    <origin xyz="0.011884 -0.0027 -0.254814" rpy="0 0 0"/>
    <geometry>
      <mesh filename="package://dexhand_description/meshes/left/ring_bulk_left_1.stl" scale="0.001 0.001 0.001"/>
    </geometry>
  </collision>
</link>

<link name="pinky_bulk_left_1">
  <inertial>
    <origin xyz="0.0027268942355102316 0.022196506510013668 0.03641042544359541" rpy="0 0 0"/>
    <mass value="0.11417783762661171"/>
    <inertia ixx="0.000111" iyy="0.000112" izz="1e-05" ixy="-1e-06" iyz="-1.3e-05" ixz="-1e-05"/>
  </inertial>
  <visual>
    <origin xyz="0.011884 -0.009438 -0.254814" rpy="0 0 0"/>
    <geometry>
      <mesh filename="package://dexhand_description/meshes/left/pinky_bulk_left_1.stl" scale="0.001 0.001 0.001"/>
    </geometry>
    <material name="silver"/>
  </visual>
  <collision>
    <origin xyz="0.011884 -0.009438 -0.254814" rpy="0 0 0"/>
    <geometry>
      <mesh filename="package://dexhand_description/meshes/left/pinky_bulk_left_1.stl" scale="0.001 0.001 0.001"/>
    </geometry>
  </collision>
</link>

<link name="thumb_cmc_b_1">
  <inertial>
    <origin xyz="0.0033566021448640723 -0.005808181561736979 -0.00814169684457966" rpy="0 0 0"/>
    <mass value="0.008494087027059793"/>
    <inertia ixx="0.0" iyy="0.0" izz="0.0" ixy="0.0" iyz="-0.0" ixz="0.0"/>
  </inertial>
  <visual>
    <origin xyz="-0.016164 0.020749 -0.265286" rpy="0 0 0"/>
    <geometry>
      <mesh filename="package://dexhand_description/meshes/left/thumb_cmc_b_1.stl" scale="0.001 0.001 0.001"/>
    </geometry>
    <material name="silver"/>
  </visual>
  <collision>
    <origin xyz="-0.016164 0.020749 -0.265286" rpy="0 0 0"/>
    <geometry>
      <mesh filename="package://dexhand_description/meshes/left/thumb_cmc_b_1.stl" scale="0.001 0.001 0.001"/>
    </geometry>
  </collision>
</link>

<link name="thumb_cmc_a_1">
  <inertial>
    <origin xyz="0.0029040235619812588 -0.0050790789776411285 0.005851148405590978" rpy="0 0 0"/>
    <mass value="0.015039242610946097"/>
    <inertia ixx="0.0" iyy="0.0" izz="0.0" ixy="-0.0" iyz="0.0" ixz="-0.0"/>
  </inertial>
  <visual>
    <origin xyz="-0.018999 0.025645 -0.256093" rpy="0 0 0"/>
    <geometry>
      <mesh filename="package://dexhand_description/meshes/left/thumb_cmc_a_1.stl" scale="0.001 0.001 0.001"/>
    </geometry>
    <material name="silver"/>
  </visual>
  <collision>
    <origin xyz="-0.018999 0.025645 -0.256093" rpy="0 0 0"/>
    <geometry>
      <mesh filename="package://dexhand_description/meshes/left/thumb_cmc_a_1.stl" scale="0.001 0.001 0.001"/>
    </geometry>
  </collision>
</link>

<link name="thumb_plp_1">
  <inertial>
    <origin xyz="0.01948596550169868 -0.01752527298585293 0.01661555837483286" rpy="0 0 0"/>
    <mass value="0.06710748615776632"/>
    <inertia ixx="2.1e-05" iyy="1.5e-05" izz="1.3e-05" ixy="5e-06" iyz="9e-06" ixz="-5e-06"/>
  </inertial>
  <visual>
    <origin xyz="-0.015836 0.036432 -0.263854" rpy="0 0 0"/>
    <geometry>
      <mesh filename="package://dexhand_description/meshes/left/thumb_plp_1.stl" scale="0.001 0.001 0.001"/>
    </geometry>
    <material name="silver"/>
  </visual>
  <collision>
    <origin xyz="-0.015836 0.036432 -0.263854" rpy="0 0 0"/>
    <geometry>
      <mesh filename="package://dexhand_description/meshes/left/thumb_plp_1.stl" scale="0.001 0.001 0.001"/>
    </geometry>
  </collision>
</link>

<link name="thumb_mlp_1">
  <inertial>
    <origin xyz="0.012445308919413409 -0.009667817552507701 0.012743810456854687" rpy="0 0 0"/>
    <mass value="0.025187203449803457"/>
    <inertia ixx="2e-06" iyy="2e-06" izz="2e-06" ixy="0.0" iyz="1e-06" ixz="-0.0"/>
  </inertial>
  <visual>
    <origin xyz="-0.040303 0.074568 -0.303457" rpy="0 0 0"/>
    <geometry>
      <mesh filename="package://dexhand_description/meshes/left/thumb_mlp_1.stl" scale="0.001 0.001 0.001"/>
    </geometry>
    <material name="silver"/>
  </visual>
  <collision>
    <origin xyz="-0.040303 0.074568 -0.303457" rpy="0 0 0"/>
    <geometry>
      <mesh filename="package://dexhand_description/meshes/left/thumb_mlp_1.stl" scale="0.001 0.001 0.001"/>
    </geometry>
  </collision>
</link>

<link name="thumb_tip_1">
  <inertial>
    <origin xyz="0.009236914086245843 -0.004264435853806994 0.007473891309465075" rpy="0 0 0"/>
    <mass value="0.02316990761545859"/>
    <inertia ixx="2e-06" iyy="1e-06" izz="2e-06" ixy="0.0" iyz="1e-06" ixz="-0.0"/>
  </inertial>
  <visual>
    <origin xyz="-0.054935 0.100147 -0.330506" rpy="0 0 0"/>
    <geometry>
      <mesh filename="package://dexhand_description/meshes/left/thumb_tip_1.stl" scale="0.001 0.001 0.001"/>
    </geometry>
    <material name="silver"/>
  </visual>
  <collision>
    <origin xyz="-0.054935 0.100147 -0.330506" rpy="0 0 0"/>
    <geometry>
      <mesh filename="package://dexhand_description/meshes/left/thumb_tip_1.stl" scale="0.001 0.001 0.001"/>
    </geometry>
  </collision>
</link>

<link name="index_knuckle_1">
  <inertial>
    <origin xyz="0.009885035151940528 0.0007944006102220333 0.0011491980522007617" rpy="0 0 0"/>
    <mass value="0.016772407452453803"/>
    <inertia ixx="1e-06" iyy="1e-06" izz="1e-06" ixy="-0.0" iyz="-0.0" ixz="-0.0"/>
  </inertial>
  <visual>
    <origin xyz="0.018773 0.0304 -0.340105" rpy="0 0 0"/>
    <geometry>
      <mesh filename="package://dexhand_description/meshes/left/index_knuckle_1.stl" scale="0.001 0.001 0.001"/>
    </geometry>
    <material name="silver"/>
  </visual>
  <collision>
    <origin xyz="0.018773 0.0304 -0.340105" rpy="0 0 0"/>
    <geometry>
      <mesh filename="package://dexhand_description/meshes/left/index_knuckle_1.stl" scale="0.001 0.001 0.001"/>
    </geometry>
  </collision>
</link>

<link name="index_plp_1">
  <inertial>
    <origin xyz="-0.006869829077265593 0.006034143678836437 0.022940322959094317" rpy="0 0 0"/>
    <mass value="0.051567105457974535"/>
    <inertia ixx="1.1e-05" iyy="1.1e-05" izz="2e-06" ixy="0.0" iyz="1e-06" ixz="0.0"/>
  </inertial>
  <visual>
    <origin xyz="0.007406 0.037699 -0.343724" rpy="0 0 0"/>
    <geometry>
      <mesh filename="package://dexhand_description/meshes/left/index_plp_1.stl" scale="0.001 0.001 0.001"/>
    </geometry>
    <material name="silver"/>
  </visual>
  <collision>
    <origin xyz="0.007406 0.037699 -0.343724" rpy="0 0 0"/>
    <geometry>
      <mesh filename="package://dexhand_description/meshes/left/index_plp_1.stl" scale="0.001 0.001 0.001"/>
    </geometry>
  </collision>
</link>

<link name="index_mlp_1">
  <inertial>
    <origin xyz="-0.001467879367556808 0.004862194442804731 0.014903889093192402" rpy="0 0 0"/>
    <mass value="0.017288956361389173"/>
    <inertia ixx="1e-06" iyy="1e-06" izz="0.0" ixy="0.0" iyz="0.0" ixz="-0.0"/>
  </inertial>
  <visual>
    <origin xyz="0.012096 0.038956 -0.388698" rpy="0 0 0"/>
    <geometry>
      <mesh filename="package://dexhand_description/meshes/left/index_mlp_1.stl" scale="0.001 0.001 0.001"/>
    </geometry>
    <material name="silver"/>
  </visual>
  <collision>
    <origin xyz="0.012096 0.038956 -0.388698" rpy="0 0 0"/>
    <geometry>
      <mesh filename="package://dexhand_description/meshes/left/index_mlp_1.stl" scale="0.001 0.001 0.001"/>
    </geometry>
  </collision>
</link>

<link name="index_tip_1">
  <inertial>
    <origin xyz="-0.0008648257503324729 0.005386014681896124 0.006769428244987441" rpy="0 0 0"/>
    <mass value="0.0160783570939756"/>
    <inertia ixx="1e-06" iyy="1e-06" izz="0.0" ixy="0.0" iyz="0.0" ixz="0.0"/>
  </inertial>
  <visual>
    <origin xyz="0.013464 0.041175 -0.418585" rpy="0 0 0"/>
    <geometry>
      <mesh filename="package://dexhand_description/meshes/left/index_tip_1.stl" scale="0.001 0.001 0.001"/>
    </geometry>
    <material name="silver"/>
  </visual>
  <collision>
    <origin xyz="0.013464 0.041175 -0.418585" rpy="0 0 0"/>
    <geometry>
      <mesh filename="package://dexhand_description/meshes/left/index_tip_1.stl" scale="0.001 0.001 0.001"/>
    </geometry>
  </collision>
</link>

<link name="middle_knuckle_1">
  <inertial>
    <origin xyz="0.009935151755682919 3.0952817304044644e-08 0.0009790823713298757" rpy="0 0 0"/>
    <mass value="0.016772407452453803"/>
    <inertia ixx="1e-06" iyy="1e-06" izz="1e-06" ixy="0.0" iyz="0.0" ixz="-0.0"/>
  </inertial>
  <visual>
    <origin xyz="0.01775 0.0063 -0.345814" rpy="0 0 0"/>
    <geometry>
      <mesh filename="package://dexhand_description/meshes/left/middle_knuckle_1.stl" scale="0.001 0.001 0.001"/>
    </geometry>
    <material name="silver"/>
  </visual>
  <collision>
    <origin xyz="0.01775 0.0063 -0.345814" rpy="0 0 0"/>
    <geometry>
      <mesh filename="package://dexhand_description/meshes/left/middle_knuckle_1.stl" scale="0.001 0.001 0.001"/>
    </geometry>
  </collision>
</link>

<link name="middle_plp_1">
  <inertial>
    <origin xyz="-0.005943828759089027 0.008200109960029896 0.023731700948842305" rpy="0 0 0"/>
    <mass value="0.05600912510930776"/>
    <inertia ixx="1.3e-05" iyy="1.3e-05" izz="2e-06" ixy="0.0" iyz="0.0" ixz="0.0"/>
  </inertial>
  <visual>
    <origin xyz="0.007 0.0143 -0.349814" rpy="0 0 0"/>
    <geometry>
      <mesh filename="package://dexhand_description/meshes/left/middle_plp_1.stl" scale="0.001 0.001 0.001"/>
    </geometry>
    <material name="silver"/>
  </visual>
  <collision>
    <origin xyz="0.007 0.0143 -0.349814" rpy="0 0 0"/>
    <geometry>
      <mesh filename="package://dexhand_description/meshes/left/middle_plp_1.stl" scale="0.001 0.001 0.001"/>
    </geometry>
  </collision>
</link>

<link name="middle_mlp_1">
  <inertial>
    <origin xyz="0.0010389909727252754 0.006301231411874452 0.015255284086023058" rpy="0 0 0"/>
    <mass value="0.019660714741942815"/>
    <inertia ixx="1e-06" iyy="1e-06" izz="1e-06" ixy="0.0" iyz="0.0" ixz="-0.0"/>
  </inertial>
  <visual>
    <origin xyz="0.011 0.0123 -0.397064" rpy="0 0 0"/>
    <geometry>
      <mesh filename="package://dexhand_description/meshes/left/middle_mlp_1.stl" scale="0.001 0.001 0.001"/>
    </geometry>
    <material name="silver"/>
  </visual>
  <collision>
    <origin xyz="0.011 0.0123 -0.397064" rpy="0 0 0"/>
    <geometry>
      <mesh filename="package://dexhand_description/meshes/left/middle_mlp_1.stl" scale="0.001 0.001 0.001"/>
    </geometry>
  </collision>
</link>

<link name="middle_tip_1">
  <inertial>
    <origin xyz="-0.0006360042284026743 0.006200203159855194 0.0068544266380235475" rpy="0 0 0"/>
    <mass value="0.0177222165691614"/>
    <inertia ixx="1e-06" iyy="1e-06" izz="0.0" ixy="0.0" iyz="0.0" ixz="0.0"/>
  </inertial>
  <visual>
    <origin xyz="0.008255 0.012299 -0.428444" rpy="0 0 0"/>
    <geometry>
      <mesh filename="package://dexhand_description/meshes/left/middle_tip_1.stl" scale="0.001 0.001 0.001"/>
    </geometry>
    <material name="silver"/>
  </visual>
  <collision>
    <origin xyz="0.008255 0.012299 -0.428444" rpy="0 0 0"/>
    <geometry>
      <mesh filename="package://dexhand_description/meshes/left/middle_tip_1.stl" scale="0.001 0.001 0.001"/>
    </geometry>
  </collision>
</link>

<link name="ring_knuckle_1">
  <inertial>
    <origin xyz="0.009906806826259634 -0.0007484681725672369 0.0009823275245010032" rpy="0 0 0"/>
    <mass value="0.016772407452453803"/>
    <inertia ixx="1e-06" iyy="1e-06" izz="1e-06" ixy="0.0" iyz="0.0" ixz="-0.0"/>
  </inertial>
  <visual>
    <origin xyz="0.016874 -0.018599 -0.34189" rpy="0 0 0"/>
    <geometry>
      <mesh filename="package://dexhand_description/meshes/left/ring_knuckle_1.stl" scale="0.001 0.001 0.001"/>
    </geometry>
    <material name="silver"/>
  </visual>
  <collision>
    <origin xyz="0.016874 -0.018599 -0.34189" rpy="0 0 0"/>
    <geometry>
      <mesh filename="package://dexhand_description/meshes/left/ring_knuckle_1.stl" scale="0.001 0.001 0.001"/>
    </geometry>
  </collision>
</link>

<link name="ring_plp_1">
  <inertial>
    <origin xyz="-0.004989026515399457 0.01123544382305516 0.021430683844999687" rpy="0 0 0"/>
    <mass value="0.051607390430851795"/>
    <inertia ixx="1.1e-05" iyy="1.1e-05" izz="2e-06" ixy="-0.0" iyz="-1e-06" ixz="-0.0"/>
  </inertial>
  <visual>
    <origin xyz="0.006818 -0.010213 -0.346802" rpy="0 0 0"/>
    <geometry>
      <mesh filename="package://dexhand_description/meshes/left/ring_plp_1.stl" scale="0.001 0.001 0.001"/>
    </geometry>
    <material name="silver"/>
  </visual>
  <collision>
    <origin xyz="0.006818 -0.010213 -0.346802" rpy="0 0 0"/>
    <geometry>
      <mesh filename="package://dexhand_description/meshes/left/ring_plp_1.stl" scale="0.001 0.001 0.001"/>
    </geometry>
  </collision>
</link>

<link name="ring_mlp_1">
  <inertial>
    <origin xyz="0.0003730974075174271 0.007646217177228753 0.013759755789535089" rpy="0 0 0"/>
    <mass value="0.017289443732746056"/>
    <inertia ixx="1e-06" iyy="1e-06" izz="0.0" ixy="-0.0" iyz="-0.0" ixz="-0.0"/>
  </inertial>
  <visual>
    <origin xyz="0.010197 -0.018042 -0.391227" rpy="0 0 0"/>
    <geometry>
      <mesh filename="package://dexhand_description/meshes/left/ring_mlp_1.stl" scale="0.001 0.001 0.001"/>
    </geometry>
    <material name="silver"/>
  </visual>
  <collision>
    <origin xyz="0.010197 -0.018042 -0.391227" rpy="0 0 0"/>
    <geometry>
      <mesh filename="package://dexhand_description/meshes/left/ring_mlp_1.stl" scale="0.001 0.001 0.001"/>
    </geometry>
  </collision>
</link>

<link name="ring_tip_1">
  <inertial>
    <origin xyz="-2.490067914703159e-05 0.006623291592850439 0.005616508181646052" rpy="0 0 0"/>
    <mass value="0.016038982608931798"/>
    <inertia ixx="1e-06" iyy="1e-06" izz="0.0" ixy="-0.0" iyz="-0.0" ixz="0.0"/>
  </inertial>
  <visual>
    <origin xyz="0.009925 -0.021514 -0.421024" rpy="0 0 0"/>
    <geometry>
      <mesh filename="package://dexhand_description/meshes/left/ring_tip_1.stl" scale="0.001 0.001 0.001"/>
    </geometry>
    <material name="silver"/>
  </visual>
  <collision>
    <origin xyz="0.009925 -0.021514 -0.421024" rpy="0 0 0"/>
    <geometry>
      <mesh filename="package://dexhand_description/meshes/left/ring_tip_1.stl" scale="0.001 0.001 0.001"/>
    </geometry>
  </collision>
</link>

<link name="pinky_knuckle_1">
  <inertial>
    <origin xyz="0.009760169679435127 -0.0017668604033237376 0.0011316142274968022" rpy="0 0 0"/>
    <mass value="0.016772407452453803"/>
    <inertia ixx="1e-06" iyy="1e-06" izz="1e-06" ixy="0.0" iyz="0.0" ixz="-0.0"/>
  </inertial>
  <visual>
    <origin xyz="0.016154 -0.040246 -0.333527" rpy="0 0 0"/>
    <geometry>
      <mesh filename="package://dexhand_description/meshes/left/pinky_knuckle_1.stl" scale="0.001 0.001 0.001"/>
    </geometry>
    <material name="silver"/>
  </visual>
  <collision>
    <origin xyz="0.016154 -0.040246 -0.333527" rpy="0 0 0"/>
    <geometry>
      <mesh filename="package://dexhand_description/meshes/left/pinky_knuckle_1.stl" scale="0.001 0.001 0.001"/>
    </geometry>
  </collision>
</link>

<link name="pinky_plp_1">
  <inertial>
    <origin xyz="-0.0038103514955992804 0.012544562388785391 0.018241923905574275" rpy="0 0 0"/>
    <mass value="0.04272741599660885"/>
    <inertia ixx="8e-06" iyy="8e-06" izz="1e-06" ixy="-0.0" iyz="-1e-06" ixz="-0.0"/>
  </inertial>
  <visual>
    <origin xyz="0.007101 -0.031122 -0.339036" rpy="0 0 0"/>
    <geometry>
      <mesh filename="package://dexhand_description/meshes/left/pinky_plp_1.stl" scale="0.001 0.001 0.001"/>
    </geometry>
    <material name="silver"/>
  </visual>
  <collision>
    <origin xyz="0.007101 -0.031122 -0.339036" rpy="0 0 0"/>
    <geometry>
      <mesh filename="package://dexhand_description/meshes/left/pinky_plp_1.stl" scale="0.001 0.001 0.001"/>
    </geometry>
  </collision>
</link>

<link name="pinky_mlp_1">
  <inertial>
    <origin xyz="0.0010486761432179307 0.007531107353638107 0.011942508707843802" rpy="0 0 0"/>
    <mass value="0.012979924052628225"/>
    <inertia ixx="1e-06" iyy="1e-06" izz="0.0" ixy="-0.0" iyz="-0.0" ixz="-0.0"/>
  </inertial>
  <visual>
    <origin xyz="0.009613 -0.041706 -0.378359" rpy="0 0 0"/>
    <geometry>
      <mesh filename="package://dexhand_description/meshes/left/pinky_mlp_1.stl" scale="0.001 0.001 0.001"/>
    </geometry>
    <material name="silver"/>
  </visual>
  <collision>
    <origin xyz="0.009613 -0.041706 -0.378359" rpy="0 0 0"/>
    <geometry>
      <mesh filename="package://dexhand_description/meshes/left/pinky_mlp_1.stl" scale="0.001 0.001 0.001"/>
    </geometry>
  </collision>
</link>

<link name="pinky_tip_1">
  <inertial>
    <origin xyz="0.000569281570460432 0.00614030199171952 0.004252130688615574" rpy="0 0 0"/>
    <mass value="0.012880734939160096"/>
    <inertia ixx="1e-06" iyy="1e-06" izz="0.0" ixy="-0.0" iyz="-0.0" ixz="0.0"/>
  </inertial>
  <visual>
    <origin xyz="0.006067 -0.045102 -0.401216" rpy="0 0 0"/>
    <geometry>
      <mesh filename="package://dexhand_description/meshes/left/pinky_tip_1.stl" scale="0.001 0.001 0.001"/>
    </geometry>
    <material name="silver"/>
  </visual>
  <collision>
    <origin xyz="0.006067 -0.045102 -0.401216" rpy="0 0 0"/>
    <geometry>
      <mesh filename="package://dexhand_description/meshes/left/pinky_tip_1.stl" scale="0.001 0.001 0.001"/>
    </geometry>
  </collision>
</link>

<link name="hand-cover-left_1">
  <inertial>
    <origin xyz="0.000995120561463822 0.040954383334705545 0.03842845525872829" rpy="0 0 0"/>
    <mass value="0.1752046644121149"/>
    <inertia ixx="0.000301" iyy="0.000157" izz="0.000241" ixy="-1.6e-05" iyz="2.5e-05" ixz="1e-06"/>
  </inertial>
  <visual>
    <origin xyz="0.011884 0.0383 -0.254814" rpy="0 0 0"/>
    <geometry>
      <mesh filename="package://dexhand_description/meshes/left/hand-cover-left_1.stl" scale="0.001 0.001 0.001"/>
    </geometry>
    <material name="silver"/>
  </visual>
  <collision>
    <origin xyz="0.011884 0.0383 -0.254814" rpy="0 0 0"/>
    <geometry>
      <mesh filename="package://dexhand_description/meshes/left/hand-cover-left_1.stl" scale="0.001 0.001 0.001"/>
    </geometry>
  </collision>
</link>

<joint name="flange" type="fixed">
  <origin xyz="0.0 0.0 0.0" rpy="0 0 0"/>
  <parent link="base_link"/>
  <child link="forearm_left_1"/>
</joint>

<joint name="wrist_pitch_lower" type="revolute">
  <origin xyz="-0.012 -0.0203 0.203" rpy="0 0 0"/>
  <parent link="forearm_left_1"/>
  <child link="wrist_lower_1"/>
  <axis xyz="-0.0 -1.0 0.0"/>
  <limit upper="0.523599" lower="-0.523599" effort="100" velocity="100"/>
</joint>

<joint name="wrist_yaw" type="revolute">
  <origin xyz="-0.01188 0.021 0.029" rpy="0 0 0"/>
  <parent link="wrist_lower_1"/>
  <child link="wrist_upper_1"/>
  <axis xyz="1.0 -0.0 -0.0"/>
  <limit upper="0.436332" lower="-0.436332" effort="100" velocity="100"/>
</joint>

<joint name="wrist_pitch_upper" type="revolute">
  <origin xyz="0.012 -0.021 0.023266" rpy="0 0 0"/>
  <parent link="wrist_upper_1"/>
  <child link="index_bulk_left_1"/>
  <axis xyz="-0.0 -1.0 -0.0"/>
  <limit upper="0.349066" lower="-0.349066" effort="100" velocity="100"/>
</joint>

<joint name="middle_bulk" type="fixed">
  <origin xyz="-4e-06 -0.006 -0.000452" rpy="0 0 0"/>
  <parent link="index_bulk_left_1"/>
  <child link="middle_bulk_left_1"/>
</joint>

<joint name="ring_bulk" type="fixed">
  <origin xyz="0.0 0.029 0.0" rpy="0 0 0"/>
  <parent link="middle_bulk_left_1"/>
  <child link="ring_bulk_left_1"/>
</joint>

<joint name="pinky_bulk" type="fixed">
  <origin xyz="0.0 0.006738 0.0" rpy="0 0 0"/>
  <parent link="ring_bulk_left_1"/>
  <child link="pinky_bulk_left_1"/>
</joint>

<joint name="thumb_yaw" type="revolute">
  <origin xyz="0.028048 0.005551 0.010472" rpy="0 0 0"/>
  <parent link="middle_bulk_left_1"/>
  <child link="thumb_cmc_b_1"/>
  <axis xyz="-0.353553 0.612372 0.707107"/>
  <limit upper="0.872665" lower="0.0" effort="100" velocity="100"/>
</joint>

<joint name="thumb_roll" type="revolute">
  <origin xyz="0.002835 -0.004896 -0.009193" rpy="0 0 0"/>
  <parent link="thumb_cmc_b_1"/>
  <child link="thumb_cmc_a_1"/>
  <axis xyz="-0.350973 0.613859 -0.707104"/>
  <limit upper="0.349066" lower="0.0" effort="100" velocity="100"/>
</joint>

<joint name="thumb_pitch" type="revolute">
  <origin xyz="-0.003163 -0.010787 0.007761" rpy="0 0 0"/>
  <parent link="thumb_cmc_a_1"/>
  <child link="thumb_plp_1"/>
  <axis xyz="-0.867074 -0.498174 -0.002105"/>
  <limit upper="0.785398" lower="0.0" effort="100" velocity="100"/>
</joint>

<joint name="thumb_knuckle" type="revolute">
  <origin xyz="0.024467 -0.038136 0.039603" rpy="0 0 0"/>
  <parent link="thumb_plp_1"/>
  <child link="thumb_mlp_1"/>
  <axis xyz="-0.867074 -0.498174 -0.002105"/>
  <limit upper="0.785398" lower="0.0" effort="100" velocity="100"/>
</joint>

<joint name="thumb_tip" type="revolute">
  <origin xyz="0.014632 -0.025579 0.027049" rpy="0 0 0"/>
  <parent link="thumb_mlp_1"/>
  <child link="thumb_tip_1"/>
  <axis xyz="-0.867074 -0.498174 -0.002105"/>
  <limit upper="0.785398" lower="0.0" effort="100" velocity="100"/>
</joint>

<joint name="index_yaw" type="revolute">
  <origin xyz="-0.006893 -0.0101 0.084839" rpy="0 0 0"/>
  <parent link="index_bulk_left_1"/>
  <child link="index_knuckle_1"/>
  <axis xyz="0.99606 0.086969 0.017358"/>
  <limit upper="0.349066" lower="-0.349066" effort="100" velocity="100"/>
</joint>

<joint name="index_pitch" type="revolute">
  <origin xyz="0.011367 -0.007299 0.003619" rpy="0 0 0"/>
  <parent link="index_knuckle_1"/>
  <child link="index_plp_1"/>
  <axis xyz="-0.087977 0.993678 0.069746"/>
  <limit upper="0.785398" lower="0.0" effort="100" velocity="100"/>
</joint>

<joint name="index_knuckle" type="revolute">
  <origin xyz="-0.00469 -0.001257 0.044974" rpy="0 0 0"/>
  <parent link="index_plp_1"/>
  <child link="index_mlp_1"/>
  <axis xyz="-0.087977 0.993678 0.069746"/>
  <limit upper="0.785398" lower="0.0" effort="100" velocity="100"/>
</joint>

<joint name="index_tip" type="revolute">
  <origin xyz="-0.001368 -0.002219 0.029887" rpy="0 0 0"/>
  <parent link="index_mlp_1"/>
  <child link="index_tip_1"/>
  <axis xyz="-0.087977 0.993678 0.069746"/>
  <limit upper="0.785398" lower="0.0" effort="100" velocity="100"/>
</joint>

<joint name="middle_yaw" type="revolute">
  <origin xyz="-0.005866 0.02 0.091" rpy="0 0 0"/>
  <parent link="middle_bulk_left_1"/>
  <child link="middle_knuckle_1"/>
  <axis xyz="1.0 0.0 -0.0"/>
  <limit upper="0.349066" lower="-0.349066" effort="100" velocity="100"/>
</joint>

<joint name="middle_pitch" type="revolute">
  <origin xyz="0.01075 -0.008 0.004" rpy="0 0 0"/>
  <parent link="middle_knuckle_1"/>
  <child link="middle_plp_1"/>
  <axis xyz="0.0 1.0 0.0"/>
  <limit upper="0.785398" lower="0.0" effort="100" velocity="100"/>
</joint>

<joint name="middle_knuckle" type="revolute">
  <origin xyz="-0.004 0.002 0.04725" rpy="0 0 0"/>
  <parent link="middle_plp_1"/>
  <child link="middle_mlp_1"/>
  <axis xyz="0.0 1.0 0.0"/>
  <limit upper="0.785398" lower="0.0" effort="100" velocity="100"/>
</joint>

<joint name="middle_tip" type="revolute">
  <origin xyz="0.002745 1e-06 0.03138" rpy="0 0 0"/>
  <parent link="middle_mlp_1"/>
  <child link="middle_tip_1"/>
  <axis xyz="0.0 1.0 0.0"/>
  <limit upper="0.785398" lower="0.0" effort="100" velocity="100"/>
</joint>

<joint name="ring_yaw" type="revolute">
  <origin xyz="-0.00499 0.015899 0.087076" rpy="0 0 0"/>
  <parent link="ring_bulk_left_1"/>
  <child link="ring_knuckle_1"/>
  <axis xyz="0.996234 -0.086694 0.001008"/>
  <limit upper="0.349066" lower="-0.349066" effort="100" velocity="100"/>
</joint>

<joint name="ring_pitch" type="revolute">
  <origin xyz="0.010056 -0.008386 0.004912" rpy="0 0 0"/>
  <parent link="ring_knuckle_1"/>
  <child link="ring_plp_1"/>
  <axis xyz="0.086225 0.989495 -0.116038"/>
  <limit upper="0.785398" lower="0.0" effort="100" velocity="100"/>
</joint>

<joint name="ring_knuckle" type="revolute">
  <origin xyz="-0.003379 0.007829 0.044425" rpy="0 0 0"/>
  <parent link="ring_plp_1"/>
  <child link="ring_mlp_1"/>
  <axis xyz="0.086225 0.989495 -0.116038"/>
  <limit upper="0.785398" lower="0.0" effort="100" velocity="100"/>
</joint>

<joint name="ring_tip" type="revolute">
  <origin xyz="0.000272 0.003472 0.029797" rpy="0 0 0"/>
  <parent link="ring_mlp_1"/>
  <child link="ring_tip_1"/>
  <axis xyz="0.086225 0.989495 -0.116038"/>
  <limit upper="0.785398" lower="0.0" effort="100" velocity="100"/>
</joint>

<joint name="pinky_yaw" type="revolute">
  <origin xyz="-0.00427 0.030808 0.078713" rpy="0 0 0"/>
  <parent link="pinky_bulk_left_1"/>
  <child link="pinky_knuckle_1"/>
  <axis xyz="0.98067 -0.194947 0.016825"/>
  <limit upper="0.349066" lower="-0.349066" effort="100" velocity="100"/>
</joint>

<joint name="pinky_pitch" type="revolute">
  <origin xyz="0.009053 -0.009124 0.005509" rpy="0 0 0"/>
  <parent link="pinky_knuckle_1"/>
  <child link="pinky_plp_1"/>
  <axis xyz="0.194878 0.965338 -0.173624"/>
  <limit upper="0.785398" lower="0.0" effort="100" velocity="100"/>
</joint>

<joint name="pinky_knuckle" type="revolute">
  <origin xyz="-0.002512 0.010584 0.039323" rpy="0 0 0"/>
  <parent link="pinky_plp_1"/>
  <child link="pinky_mlp_1"/>
  <axis xyz="0.194878 0.965338 -0.173624"/>
  <limit upper="0.785398" lower="0.0" effort="100" velocity="100"/>
</joint>

<joint name="pinky_tip" type="revolute">
  <origin xyz="0.003546 0.003396 0.022857" rpy="0 0 0"/>
  <parent link="pinky_mlp_1"/>
  <child link="pinky_tip_1"/>
  <axis xyz="0.194878 0.965338 -0.173624"/>
  <limit upper="0.785398" lower="0.0" effort="100" velocity="100"/>
</joint>

<joint name="hand_cover" type="fixed">
  <origin xyz="0.0 -0.012 0.0" rpy="0 0 0"/>
  <parent link="middle_bulk_left_1"/>
  <child link="hand-cover-left_1"/>
</joint>

</robot>
