<?xml version="1.0" ?>
<robot name="dexhand" xmlns:xacro="http://www.ros.org/wiki/xacro">

<xacro:include filename="$(find dexhand_description)/urdf/materials.xacro" />
<xacro:include filename="$(find dexhand_description)/urdf/dexhand.trans" />
<xacro:include filename="$(find dexhand_description)/urdf/dexhand.gazebo" />
<link name="base_link">
  <inertial>
    <origin xyz="-5.952490372344805e-18 -5.952490372344805e-18 0.00625299730853927" rpy="0 0 0"/>
    <mass value="0.3748186138447861"/>
    <inertia ixx="0.000121" iyy="0.000121" izz="0.000233" ixy="0.0" iyz="-0.0" ixz="-0.0"/>
  </inertial>
  <visual>
    <origin xyz="0 0 0" rpy="0 0 0"/>
    <geometry>
      <mesh filename="package://dexhand_description/meshes/base_link.stl" scale="0.001 0.001 0.001"/>
    </geometry>
    <material name="silver"/>
  </visual>
  <collision>
    <origin xyz="0 0 0" rpy="0 0 0"/>
    <geometry>
      <mesh filename="package://dexhand_description/meshes/base_link.stl" scale="0.001 0.001 0.001"/>
    </geometry>
  </collision>
</link>

<link name="forearm_1">
  <inertial>
    <origin xyz="-0.0045635525882340025 -0.0024890003495871478 0.09119374176848805" rpy="0 0 0"/>
    <mass value="2.2753127167166265"/>
    <inertia ixx="0.009336" iyy="0.00912" izz="0.00247" ixy="-3.2e-05" iyz="4e-06" ixz="0.000837"/>
  </inertial>
  <visual>
    <origin xyz="-0.0 -0.0 -0.0" rpy="0 0 0"/>
    <geometry>
      <mesh filename="package://dexhand_description/meshes/forearm_1.stl" scale="0.001 0.001 0.001"/>
    </geometry>
    <material name="silver"/>
  </visual>
  <collision>
    <origin xyz="-0.0 -0.0 -0.0" rpy="0 0 0"/>
    <geometry>
      <mesh filename="package://dexhand_description/meshes/forearm_1.stl" scale="0.001 0.001 0.001"/>
    </geometry>
  </collision>
</link>

<link name="wrist-lower_1">
  <inertial>
    <origin xyz="-3.0683763790256835e-05 0.02099365535807374 0.021635071099651598" rpy="0 0 0"/>
    <mass value="0.3236409508310491"/>
    <inertia ixx="0.000132" iyy="0.000118" izz="0.000139" ixy="-0.0" iyz="-0.0" ixz="-0.0"/>
  </inertial>
  <visual>
    <origin xyz="0.012 0.0217 -0.203" rpy="0 0 0"/>
    <geometry>
      <mesh filename="package://dexhand_description/meshes/wrist-lower_1.stl" scale="0.001 0.001 0.001"/>
    </geometry>
    <material name="silver"/>
  </visual>
  <collision>
    <origin xyz="0.012 0.0217 -0.203" rpy="0 0 0"/>
    <geometry>
      <mesh filename="package://dexhand_description/meshes/wrist-lower_1.stl" scale="0.001 0.001 0.001"/>
    </geometry>
  </collision>
</link>

<link name="wrist-upper_1">
  <inertial>
    <origin xyz="0.011943478530919125 1.976395235870395e-08 0.007146961841600852" rpy="0 0 0"/>
    <mass value="0.12131953205677495"/>
    <inertia ixx="3.3e-05" iyy="2.2e-05" izz="2.6e-05" ixy="0.0" iyz="-0.0" ixz="-0.0"/>
  </inertial>
  <visual>
    <origin xyz="0.02398 0.0007 -0.232" rpy="0 0 0"/>
    <geometry>
      <mesh filename="package://dexhand_description/meshes/wrist-upper_1.stl" scale="0.001 0.001 0.001"/>
    </geometry>
    <material name="silver"/>
  </visual>
  <collision>
    <origin xyz="0.02398 0.0007 -0.232" rpy="0 0 0"/>
    <geometry>
      <mesh filename="package://dexhand_description/meshes/wrist-upper_1.stl" scale="0.001 0.001 0.001"/>
    </geometry>
  </collision>
</link>

<link name="index-bulk_1">
  <inertial>
    <origin xyz="0.001953836875769263 0.005732502869548333 0.04310739786858114" rpy="0 0 0"/>
    <mass value="0.10571474174321724"/>
    <inertia ixx="0.000112" iyy="0.000114" izz="8e-06" ixy="-0.0" iyz="-6e-06" ixz="-7e-06"/>
  </inertial>
  <visual>
    <origin xyz="0.01198 -0.0203 -0.255266" rpy="0 0 0"/>
    <geometry>
      <mesh filename="package://dexhand_description/meshes/index-bulk_1.stl" scale="0.001 0.001 0.001"/>
    </geometry>
    <material name="silver"/>
  </visual>
  <collision>
    <origin xyz="0.01198 -0.0203 -0.255266" rpy="0 0 0"/>
    <geometry>
      <mesh filename="package://dexhand_description/meshes/index-bulk_1.stl" scale="0.001 0.001 0.001"/>
    </geometry>
  </collision>
</link>

<link name="middle-bulk_1">
  <inertial>
    <origin xyz="0.01064695002640492 -0.0158135798135519 0.030689623412746947" rpy="0 0 0"/>
    <mass value="0.23199631248210004"/>
    <inertia ixx="0.000258" iyy="0.000268" izz="7.1e-05" ixy="-1.4e-05" iyz="4.2e-05" ixz="4e-05"/>
  </inertial>
  <visual>
    <origin xyz="0.01198 -0.0263 -0.255266" rpy="0 0 0"/>
    <geometry>
      <mesh filename="package://dexhand_description/meshes/middle-bulk_1.stl" scale="0.001 0.001 0.001"/>
    </geometry>
    <material name="silver"/>
  </visual>
  <collision>
    <origin xyz="0.01198 -0.0263 -0.255266" rpy="0 0 0"/>
    <geometry>
      <mesh filename="package://dexhand_description/meshes/middle-bulk_1.stl" scale="0.001 0.001 0.001"/>
    </geometry>
  </collision>
</link>

<link name="ring-bulk_1">
  <inertial>
    <origin xyz="0.003391811603104285 -0.01025124324374128 0.05277806405684754" rpy="0 0 0"/>
    <mass value="0.09588694429304498"/>
    <inertia ixx="7.4e-05" iyy="7.4e-05" izz="7e-06" ixy="1e-06" iyz="8e-06" ixz="-7e-06"/>
  </inertial>
  <visual>
    <origin xyz="0.01198 0.0027 -0.255266" rpy="0 0 0"/>
    <geometry>
      <mesh filename="package://dexhand_description/meshes/ring-bulk_1.stl" scale="0.001 0.001 0.001"/>
    </geometry>
    <material name="silver"/>
  </visual>
  <collision>
    <origin xyz="0.01198 0.0027 -0.255266" rpy="0 0 0"/>
    <geometry>
      <mesh filename="package://dexhand_description/meshes/ring-bulk_1.stl" scale="0.001 0.001 0.001"/>
    </geometry>
  </collision>
</link>

<link name="index-knuckle_1">
  <inertial>
    <origin xyz="0.007134673083101478 -0.0005540875413111747 0.0011013348331220807" rpy="0 0 0"/>
    <mass value="0.016772407452453803"/>
    <inertia ixx="1e-06" iyy="1e-06" izz="1e-06" ixy="0.0" iyz="0.0" ixz="-0.0"/>
  </inertial>
  <visual>
    <origin xyz="0.015885 -0.030139 -0.340157" rpy="0 0 0"/>
    <geometry>
      <mesh filename="package://dexhand_description/meshes/index-knuckle_1.stl" scale="0.001 0.001 0.001"/>
    </geometry>
    <material name="silver"/>
  </visual>
  <collision>
    <origin xyz="0.015885 -0.030139 -0.340157" rpy="0 0 0"/>
    <geometry>
      <mesh filename="package://dexhand_description/meshes/index-knuckle_1.stl" scale="0.001 0.001 0.001"/>
    </geometry>
  </collision>
</link>

<link name="middle-knuckle_1">
  <inertial>
    <origin xyz="0.006935399474227782 3.095281810635425e-08 0.0009794888636300847" rpy="0 0 0"/>
    <mass value="0.016772407452453803"/>
    <inertia ixx="1e-06" iyy="1e-06" izz="1e-06" ixy="0.0" iyz="0.0" ixz="-0.0"/>
  </inertial>
  <visual>
    <origin xyz="0.014846 -0.0063 -0.346266" rpy="0 0 0"/>
    <geometry>
      <mesh filename="package://dexhand_description/meshes/middle-knuckle_1.stl" scale="0.001 0.001 0.001"/>
    </geometry>
    <material name="silver"/>
  </visual>
  <collision>
    <origin xyz="0.014846 -0.0063 -0.346266" rpy="0 0 0"/>
    <geometry>
      <mesh filename="package://dexhand_description/meshes/middle-knuckle_1.stl" scale="0.001 0.001 0.001"/>
    </geometry>
  </collision>
</link>

<link name="ring-knuckle_1">
  <inertial>
    <origin xyz="0.006918049206992894 0.0004875294278836907 0.0009797412002323647" rpy="0 0 0"/>
    <mass value="0.016772407452453803"/>
    <inertia ixx="1e-06" iyy="1e-06" izz="1e-06" ixy="-0.0" iyz="-0.0" ixz="-0.0"/>
  </inertial>
  <visual>
    <origin xyz="0.013981 0.018338 -0.342345" rpy="0 0 0"/>
    <geometry>
      <mesh filename="package://dexhand_description/meshes/ring-knuckle_1.stl" scale="0.001 0.001 0.001"/>
    </geometry>
    <material name="silver"/>
  </visual>
  <collision>
    <origin xyz="0.013981 0.018338 -0.342345" rpy="0 0 0"/>
    <geometry>
      <mesh filename="package://dexhand_description/meshes/ring-knuckle_1.stl" scale="0.001 0.001 0.001"/>
    </geometry>
  </collision>
</link>

<link name="pinky-knuckle_1">
  <inertial>
    <origin xyz="0.006818820473942549 0.0011824337110899266 0.0010801856787569508" rpy="0 0 0"/>
    <mass value="0.016772407452453803"/>
    <inertia ixx="1e-06" iyy="1e-06" izz="1e-06" ixy="-0.0" iyz="-0.0" ixz="-0.0"/>
  </inertial>
  <visual>
    <origin xyz="0.013416 0.038945 -0.334029" rpy="0 0 0"/>
    <geometry>
      <mesh filename="package://dexhand_description/meshes/pinky-knuckle_1.stl" scale="0.001 0.001 0.001"/>
    </geometry>
    <material name="silver"/>
  </visual>
  <collision>
    <origin xyz="0.013416 0.038945 -0.334029" rpy="0 0 0"/>
    <geometry>
      <mesh filename="package://dexhand_description/meshes/pinky-knuckle_1.stl" scale="0.001 0.001 0.001"/>
    </geometry>
  </collision>
</link>

<link name="index-plp_1">
  <inertial>
    <origin xyz="-0.006869198158126709 -0.006033909809302199 0.022940465298997237" rpy="0 0 0"/>
    <mass value="0.051567105457974535"/>
    <inertia ixx="1.1e-05" iyy="1.1e-05" izz="2e-06" ixy="-0.0" iyz="-1e-06" ixz="0.0"/>
  </inertial>
  <visual>
    <origin xyz="0.007269 -0.037678 -0.343728" rpy="0 0 0"/>
    <geometry>
      <mesh filename="package://dexhand_description/meshes/index-plp_1.stl" scale="0.001 0.001 0.001"/>
    </geometry>
    <material name="silver"/>
  </visual>
  <collision>
    <origin xyz="0.007269 -0.037678 -0.343728" rpy="0 0 0"/>
    <geometry>
      <mesh filename="package://dexhand_description/meshes/index-plp_1.stl" scale="0.001 0.001 0.001"/>
    </geometry>
  </collision>
</link>

<link name="index-mlp_1">
  <inertial>
    <origin xyz="-0.0014672452336520862 -0.004861924263139264 0.014904028884496323" rpy="0 0 0"/>
    <mass value="0.017288956361389173"/>
    <inertia ixx="1e-06" iyy="1e-06" izz="0.0" ixy="-0.0" iyz="-0.0" ixz="-0.0"/>
  </inertial>
  <visual>
    <origin xyz="0.011959 -0.038935 -0.388702" rpy="0 0 0"/>
    <geometry>
      <mesh filename="package://dexhand_description/meshes/index-mlp_1.stl" scale="0.001 0.001 0.001"/>
    </geometry>
    <material name="silver"/>
  </visual>
  <collision>
    <origin xyz="0.011959 -0.038935 -0.388702" rpy="0 0 0"/>
    <geometry>
      <mesh filename="package://dexhand_description/meshes/index-mlp_1.stl" scale="0.001 0.001 0.001"/>
    </geometry>
  </collision>
</link>

<link name="index-tip_1">
  <inertial>
    <origin xyz="-0.000864193964734649 -0.005385771025884167 0.006769569897979166" rpy="0 0 0"/>
    <mass value="0.0160783570939756"/>
    <inertia ixx="1e-06" iyy="1e-06" izz="0.0" ixy="-0.0" iyz="-0.0" ixz="0.0"/>
  </inertial>
  <visual>
    <origin xyz="0.013327 -0.041154 -0.418589" rpy="0 0 0"/>
    <geometry>
      <mesh filename="package://dexhand_description/meshes/index-tip_1.stl" scale="0.001 0.001 0.001"/>
    </geometry>
    <material name="silver"/>
  </visual>
  <collision>
    <origin xyz="0.013327 -0.041154 -0.418589" rpy="0 0 0"/>
    <geometry>
      <mesh filename="package://dexhand_description/meshes/index-tip_1.stl" scale="0.001 0.001 0.001"/>
    </geometry>
  </collision>
</link>

<link name="pinky-bulk_1">
  <inertial>
    <origin xyz="0.0027271468848747375 -0.00919661076399992 0.036410887836454076" rpy="0 0 0"/>
    <mass value="0.11417768838788588"/>
    <inertia ixx="0.000111" iyy="0.000112" izz="1e-05" ixy="1e-06" iyz="1.3e-05" ixz="-1e-05"/>
  </inertial>
  <visual>
    <origin xyz="0.01198 0.0217 -0.255266" rpy="0 0 0"/>
    <geometry>
      <mesh filename="package://dexhand_description/meshes/pinky-bulk_1.stl" scale="0.001 0.001 0.001"/>
    </geometry>
    <material name="silver"/>
  </visual>
  <collision>
    <origin xyz="0.01198 0.0217 -0.255266" rpy="0 0 0"/>
    <geometry>
      <mesh filename="package://dexhand_description/meshes/pinky-bulk_1.stl" scale="0.001 0.001 0.001"/>
    </geometry>
  </collision>
</link>

<link name="middle-plp_1">
  <inertial>
    <origin xyz="-0.005943581040544219 -0.008199991640619155 0.023732107441142736" rpy="0 0 0"/>
    <mass value="0.05600912510930776"/>
    <inertia ixx="1.3e-05" iyy="1.3e-05" izz="2e-06" ixy="0.0" iyz="0.0" ixz="0.0"/>
  </inertial>
  <visual>
    <origin xyz="0.007096 -0.0143 -0.350266" rpy="0 0 0"/>
    <geometry>
      <mesh filename="package://dexhand_description/meshes/middle-plp_1.stl" scale="0.001 0.001 0.001"/>
    </geometry>
    <material name="silver"/>
  </visual>
  <collision>
    <origin xyz="0.007096 -0.0143 -0.350266" rpy="0 0 0"/>
    <geometry>
      <mesh filename="package://dexhand_description/meshes/middle-plp_1.stl" scale="0.001 0.001 0.001"/>
    </geometry>
  </collision>
</link>

<link name="middle-mlp_1">
  <inertial>
    <origin xyz="-0.0002942937668230297 -0.006300032078833903 0.01528820861860325" rpy="0 0 0"/>
    <mass value="0.019660714741942815"/>
    <inertia ixx="1e-06" iyy="1e-06" izz="1e-06" ixy="0.0" iyz="0.0" ixz="-0.0"/>
  </inertial>
  <visual>
    <origin xyz="0.011096 -0.0123 -0.397516" rpy="0 0 0"/>
    <geometry>
      <mesh filename="package://dexhand_description/meshes/middle-mlp_1.stl" scale="0.001 0.001 0.001"/>
    </geometry>
    <material name="silver"/>
  </visual>
  <collision>
    <origin xyz="0.011096 -0.0123 -0.397516" rpy="0 0 0"/>
    <geometry>
      <mesh filename="package://dexhand_description/meshes/middle-mlp_1.stl" scale="0.001 0.001 0.001"/>
    </geometry>
  </collision>
</link>

<link name="middle-tip_1">
  <inertial>
    <origin xyz="-0.0006361624064091121 -0.006200060330852967 0.006854700140433545" rpy="0 0 0"/>
    <mass value="0.0177222165691614"/>
    <inertia ixx="1e-06" iyy="1e-06" izz="0.0" ixy="0.0" iyz="0.0" ixz="0.0"/>
  </inertial>
  <visual>
    <origin xyz="0.011096 -0.0123 -0.429016" rpy="0 0 0"/>
    <geometry>
      <mesh filename="package://dexhand_description/meshes/middle-tip_1.stl" scale="0.001 0.001 0.001"/>
    </geometry>
    <material name="silver"/>
  </visual>
  <collision>
    <origin xyz="0.011096 -0.0123 -0.429016" rpy="0 0 0"/>
    <geometry>
      <mesh filename="package://dexhand_description/meshes/middle-tip_1.stl" scale="0.001 0.001 0.001"/>
    </geometry>
  </collision>
</link>

<link name="ring-plp_1">
  <inertial>
    <origin xyz="-0.004988778025381063 -0.011235452676283272 0.021431089299078554" rpy="0 0 0"/>
    <mass value="0.051607390430851795"/>
    <inertia ixx="1.1e-05" iyy="1.1e-05" izz="2e-06" ixy="0.0" iyz="1e-06" ixz="-0.0"/>
  </inertial>
  <visual>
    <origin xyz="0.006914 0.010213 -0.347254" rpy="0 0 0"/>
    <geometry>
      <mesh filename="package://dexhand_description/meshes/ring-plp_1.stl" scale="0.001 0.001 0.001"/>
    </geometry>
    <material name="silver"/>
  </visual>
  <collision>
    <origin xyz="0.006914 0.010213 -0.347254" rpy="0 0 0"/>
    <geometry>
      <mesh filename="package://dexhand_description/meshes/ring-plp_1.stl" scale="0.001 0.001 0.001"/>
    </geometry>
  </collision>
</link>

<link name="ring-mlp_1">
  <inertial>
    <origin xyz="0.0003732140836782156 -0.00764471336941365 0.013759338633879348" rpy="0 0 0"/>
    <mass value="0.017289443732746056"/>
    <inertia ixx="1e-06" iyy="1e-06" izz="0.0" ixy="0.0" iyz="0.0" ixz="-0.0"/>
  </inertial>
  <visual>
    <origin xyz="0.010293 0.018042 -0.39168" rpy="0 0 0"/>
    <geometry>
      <mesh filename="package://dexhand_description/meshes/ring-mlp_1.stl" scale="0.001 0.001 0.001"/>
    </geometry>
    <material name="silver"/>
  </visual>
  <collision>
    <origin xyz="0.010293 0.018042 -0.39168" rpy="0 0 0"/>
    <geometry>
      <mesh filename="package://dexhand_description/meshes/ring-mlp_1.stl" scale="0.001 0.001 0.001"/>
    </geometry>
  </collision>
</link>

<link name="ring-tip_1">
  <inertial>
    <origin xyz="-2.4752226243757516e-05 -0.006623152446546366 0.00561604826201334" rpy="0 0 0"/>
    <mass value="0.016038982608931798"/>
    <inertia ixx="1e-06" iyy="1e-06" izz="0.0" ixy="0.0" iyz="0.0" ixz="0.0"/>
  </inertial>
  <visual>
    <origin xyz="0.010021 0.021513 -0.421477" rpy="0 0 0"/>
    <geometry>
      <mesh filename="package://dexhand_description/meshes/ring-tip_1.stl" scale="0.001 0.001 0.001"/>
    </geometry>
    <material name="silver"/>
  </visual>
  <collision>
    <origin xyz="0.010021 0.021513 -0.421477" rpy="0 0 0"/>
    <geometry>
      <mesh filename="package://dexhand_description/meshes/ring-tip_1.stl" scale="0.001 0.001 0.001"/>
    </geometry>
  </collision>
</link>

<link name="pinky-plp_1">
  <inertial>
    <origin xyz="-0.003810668938620476 -0.012545146418320559 0.01824146705849028" rpy="0 0 0"/>
    <mass value="0.04272741599660885"/>
    <inertia ixx="8e-06" iyy="8e-06" izz="1e-06" ixy="0.0" iyz="1e-06" ixz="-0.0"/>
  </inertial>
  <visual>
    <origin xyz="0.007304 0.030405 -0.339487" rpy="0 0 0"/>
    <geometry>
      <mesh filename="package://dexhand_description/meshes/pinky-plp_1.stl" scale="0.001 0.001 0.001"/>
    </geometry>
    <material name="silver"/>
  </visual>
  <collision>
    <origin xyz="0.007304 0.030405 -0.339487" rpy="0 0 0"/>
    <geometry>
      <mesh filename="package://dexhand_description/meshes/pinky-plp_1.stl" scale="0.001 0.001 0.001"/>
    </geometry>
  </collision>
</link>

<link name="pinky-mlp_1">
  <inertial>
    <origin xyz="0.001048124969384794 -0.00753053358362181 0.011942260100064106" rpy="0 0 0"/>
    <mass value="0.012979924052628225"/>
    <inertia ixx="1e-06" iyy="1e-06" izz="0.0" ixy="0.0" iyz="0.0" ixz="-0.0"/>
  </inertial>
  <visual>
    <origin xyz="0.009816 0.040989 -0.37881" rpy="0 0 0"/>
    <geometry>
      <mesh filename="package://dexhand_description/meshes/pinky-mlp_1.stl" scale="0.001 0.001 0.001"/>
    </geometry>
    <material name="silver"/>
  </visual>
  <collision>
    <origin xyz="0.009816 0.040989 -0.37881" rpy="0 0 0"/>
    <geometry>
      <mesh filename="package://dexhand_description/meshes/pinky-mlp_1.stl" scale="0.001 0.001 0.001"/>
    </geometry>
  </collision>
</link>

<link name="pinky-tip_1">
  <inertial>
    <origin xyz="0.0005692184398215418 -0.006140261264943145 0.004252021497514635" rpy="0 0 0"/>
    <mass value="0.012880734939160096"/>
    <inertia ixx="1e-06" iyy="1e-06" izz="0.0" ixy="0.0" iyz="0.0" ixz="0.0"/>
  </inertial>
  <visual>
    <origin xyz="0.009341 0.045675 -0.405396" rpy="0 0 0"/>
    <geometry>
      <mesh filename="package://dexhand_description/meshes/pinky-tip_1.stl" scale="0.001 0.001 0.001"/>
    </geometry>
    <material name="silver"/>
  </visual>
  <collision>
    <origin xyz="0.009341 0.045675 -0.405396" rpy="0 0 0"/>
    <geometry>
      <mesh filename="package://dexhand_description/meshes/pinky-tip_1.stl" scale="0.001 0.001 0.001"/>
    </geometry>
  </collision>
</link>

<joint name="flange" type="fixed">
  <origin xyz="0.0 0.0 0.0" rpy="0 0 0"/>
  <parent link="base_link"/>
  <child link="forearm_1"/>
</joint>

<joint name="wrist_pitch" type="revolute">
  <origin xyz="-0.012 -0.0217 0.203" rpy="0 0 0"/>
  <parent link="forearm_1"/>
  <child link="wrist-lower_1"/>
  <axis xyz="0.0 -1.0 0.0"/>
  <limit upper="0.523599" lower="-0.523599" effort="100" velocity="100"/>
</joint>

<joint name="wrist_yaw" type="revolute">
  <origin xyz="-0.01198 0.021 0.029" rpy="0 0 0"/>
  <parent link="wrist-lower_1"/>
  <child link="wrist-upper_1"/>
  <axis xyz="-1.0 0.0 0.0"/>
  <limit upper="0.436332" lower="-0.436332" effort="100" velocity="100"/>
</joint>

<joint name="index-bulk" type="fixed">
  <origin xyz="0.012 0.021 0.023266" rpy="0 0 0"/>
  <parent link="wrist-upper_1"/>
  <child link="index-bulk_1"/>
</joint>

<joint name="middle-bulk" type="fixed">
  <origin xyz="0.0 0.006 0.0" rpy="0 0 0"/>
  <parent link="index-bulk_1"/>
  <child link="middle-bulk_1"/>
</joint>

<joint name="ring-bulk" type="fixed">
  <origin xyz="0.0 -0.029 0.0" rpy="0 0 0"/>
  <parent link="middle-bulk_1"/>
  <child link="ring-bulk_1"/>
</joint>

<joint name="index-yaw" type="revolute">
  <origin xyz="-0.003905 0.009839 0.084891" rpy="0 0 0"/>
  <parent link="index-bulk_1"/>
  <child link="index-knuckle_1"/>
  <axis xyz="-0.99606 0.086969 -0.017358"/>
  <limit upper="0.349066" lower="-0.349066" effort="100" velocity="100"/>
</joint>

<joint name="middle-yaw" type="revolute">
  <origin xyz="-0.002866 -0.02 0.091" rpy="0 0 0"/>
  <parent link="middle-bulk_1"/>
  <child link="middle-knuckle_1"/>
  <axis xyz="-1.0 -0.0 0.0"/>
  <limit upper="0.349066" lower="-0.349066" effort="100" velocity="100"/>
</joint>

<joint name="ring-yaw" type="revolute">
  <origin xyz="-0.002001 -0.015638 0.087079" rpy="0 0 0"/>
  <parent link="ring-bulk_1"/>
  <child link="ring-knuckle_1"/>
  <axis xyz="-0.996234 -0.086694 -0.001008"/>
  <limit upper="0.349066" lower="-0.349066" effort="100" velocity="100"/>
</joint>

<joint name="pinky-yaw" type="revolute">
  <origin xyz="-0.001436 -0.017245 0.078763" rpy="0 0 0"/>
  <parent link="pinky-bulk_1"/>
  <child link="pinky-knuckle_1"/>
  <axis xyz="-0.98067 -0.194947 -0.016825"/>
  <limit upper="0.349066" lower="-0.349066" effort="100" velocity="100"/>
</joint>

<joint name="index-pitch" type="revolute">
  <origin xyz="0.008616 0.007539 0.003571" rpy="0 0 0"/>
  <parent link="index-knuckle_1"/>
  <child link="index-plp_1"/>
  <axis xyz="0.087977 0.993678 -0.069746"/>
  <limit upper="0.785398" lower="0.0" effort="100" velocity="100"/>
</joint>

<joint name="index-knuckle" type="revolute">
  <origin xyz="-0.00469 0.001257 0.044974" rpy="0 0 0"/>
  <parent link="index-plp_1"/>
  <child link="index-mlp_1"/>
  <axis xyz="0.087977 0.993678 -0.069746"/>
  <limit upper="0.785398" lower="0.0" effort="100" velocity="100"/>
</joint>

<joint name="index-tip" type="revolute">
  <origin xyz="-0.001368 0.002219 0.029887" rpy="0 0 0"/>
  <parent link="index-mlp_1"/>
  <child link="index-tip_1"/>
  <axis xyz="0.087977 0.993678 -0.069746"/>
  <limit upper="0.785398" lower="0.0" effort="100" velocity="100"/>
</joint>

<joint name="pinky-bulk" type="fixed">
  <origin xyz="0.012 -0.021 0.023266" rpy="0 0 0"/>
  <parent link="wrist-upper_1"/>
  <child link="pinky-bulk_1"/>
</joint>

<joint name="middle-pitch" type="revolute">
  <origin xyz="0.00775 0.008 0.004" rpy="0 0 0"/>
  <parent link="middle-knuckle_1"/>
  <child link="middle-plp_1"/>
  <axis xyz="0.0 1.0 0.0"/>
  <limit upper="0.785398" lower="0.0" effort="100" velocity="100"/>
</joint>

<joint name="middle-knuckle" type="revolute">
  <origin xyz="-0.004 -0.002 0.04725" rpy="0 0 0"/>
  <parent link="middle-plp_1"/>
  <child link="middle-mlp_1"/>
  <axis xyz="-0.0 1.0 0.0"/>
  <limit upper="0.785398" lower="0.0" effort="100" velocity="100"/>
</joint>

<joint name="middle-tip" type="revolute">
  <origin xyz="0.0 0.0 0.0315" rpy="0 0 0"/>
  <parent link="middle-mlp_1"/>
  <child link="middle-tip_1"/>
  <axis xyz="-0.0 1.0 0.0"/>
  <limit upper="0.785398" lower="0.0" effort="100" velocity="100"/>
</joint>

<joint name="ring-pitch" type="revolute">
  <origin xyz="0.007067 0.008125 0.004909" rpy="0 0 0"/>
  <parent link="ring-knuckle_1"/>
  <child link="ring-plp_1"/>
  <axis xyz="-0.086225 0.989495 0.116038"/>
  <limit upper="0.785398" lower="0.0" effort="100" velocity="100"/>
</joint>

<joint name="ring-knuckle" type="revolute">
  <origin xyz="-0.003379 -0.007829 0.044426" rpy="0 0 0"/>
  <parent link="ring-plp_1"/>
  <child link="ring-mlp_1"/>
  <axis xyz="-0.086225 0.989495 0.116038"/>
  <limit upper="0.785398" lower="0.0" effort="100" velocity="100"/>
</joint>

<joint name="ring-tip" type="revolute">
  <origin xyz="0.000272 -0.003471 0.029797" rpy="0 0 0"/>
  <parent link="ring-mlp_1"/>
  <child link="ring-tip_1"/>
  <axis xyz="-0.086225 0.989495 0.116038"/>
  <limit upper="0.785398" lower="0.0" effort="100" velocity="100"/>
</joint>

<joint name="pinky-pitch" type="revolute">
  <origin xyz="0.006112 0.00854 0.005458" rpy="0 0 0"/>
  <parent link="pinky-knuckle_1"/>
  <child link="pinky-plp_1"/>
  <axis xyz="-0.194878 0.965338 0.173624"/>
  <limit upper="0.785398" lower="0.0" effort="100" velocity="100"/>
</joint>

<joint name="pinky-knuckle" type="revolute">
  <origin xyz="-0.002512 -0.010584 0.039323" rpy="0 0 0"/>
  <parent link="pinky-plp_1"/>
  <child link="pinky-mlp_1"/>
  <axis xyz="-0.194878 0.965338 0.173624"/>
  <limit upper="0.785398" lower="0.0" effort="100" velocity="100"/>
</joint>

<joint name="pinky-tip" type="revolute">
  <origin xyz="0.000475 -0.004686 0.026586" rpy="0 0 0"/>
  <parent link="pinky-mlp_1"/>
  <child link="pinky-tip_1"/>
  <axis xyz="-0.194878 0.965338 0.173624"/>
  <limit upper="0.785398" lower="0.0" effort="100" velocity="100"/>
</joint>

</robot>
